Traceback (most recent call last):
  File "/usr/share/miniconda/envs/zposter38/lib/python3.8/site-packages/jupyter_cache/executors/utils.py", line 51, in single_nb_execution
    executenb(
  File "/usr/share/miniconda/envs/zposter38/lib/python3.8/site-packages/nbclient/client.py", line 1112, in execute
    return NotebookClient(nb=nb, resources=resources, km=km, **kwargs).execute()
  File "/usr/share/miniconda/envs/zposter38/lib/python3.8/site-packages/nbclient/util.py", line 74, in wrapped
    return just_run(coro(*args, **kwargs))
  File "/usr/share/miniconda/envs/zposter38/lib/python3.8/site-packages/nbclient/util.py", line 53, in just_run
    return loop.run_until_complete(coro)
  File "/usr/share/miniconda/envs/zposter38/lib/python3.8/asyncio/base_events.py", line 616, in run_until_complete
    return future.result()
  File "/usr/share/miniconda/envs/zposter38/lib/python3.8/site-packages/nbclient/client.py", line 553, in async_execute
    await self.async_execute_cell(
  File "/usr/share/miniconda/envs/zposter38/lib/python3.8/site-packages/nbclient/client.py", line 857, in async_execute_cell
    self._check_raise_for_error(cell, exec_reply)
  File "/usr/share/miniconda/envs/zposter38/lib/python3.8/site-packages/nbclient/client.py", line 760, in _check_raise_for_error
    raise CellExecutionError.from_cell_and_msg(cell, exec_reply_content)
nbclient.exceptions.CellExecutionError: An error occurred while executing the following cell:
------------------
# This shortcut function will be available in zfit, but here
# we use the core one to highlight the use of tensorflow graphs
def api_unbinned_nll(pdf, data, norm_range):
    return zfit.core.loss.unbinned_nll(pdf.prob(data, norm_range=norm_range))

mu1 = zfit.Parameter("mu", 5.0, 0., 10)
sigma1 = zfit.Parameter("sigma", 1, 0.1, 5.)
gauss1 = zfit.pdf.Gauss(mu=mu1, sigma=sigma1)

nll1 = api_unbinned_nll(gauss1, ds_gauss_at_five, (0, 20))
------------------

[0;31m---------------------------------------------------------------------------[0m
[0;31mTypeError[0m                                 Traceback (most recent call last)
[0;32m/tmp/ipykernel_2336/3125598249.py[0m in [0;36m<module>[0;34m[0m
[1;32m      6[0m [0mmu1[0m [0;34m=[0m [0mzfit[0m[0;34m.[0m[0mParameter[0m[0;34m([0m[0;34m"mu"[0m[0;34m,[0m [0;36m5.0[0m[0;34m,[0m [0;36m0.[0m[0;34m,[0m [0;36m10[0m[0;34m)[0m[0;34m[0m[0;34m[0m[0m
[1;32m      7[0m [0msigma1[0m [0;34m=[0m [0mzfit[0m[0;34m.[0m[0mParameter[0m[0;34m([0m[0;34m"sigma"[0m[0;34m,[0m [0;36m1[0m[0;34m,[0m [0;36m0.1[0m[0;34m,[0m [0;36m5.[0m[0;34m)[0m[0;34m[0m[0;34m[0m[0m
[0;32m----> 8[0;31m [0mgauss1[0m [0;34m=[0m [0mzfit[0m[0;34m.[0m[0mpdf[0m[0;34m.[0m[0mGauss[0m[0;34m([0m[0mmu[0m[0;34m=[0m[0mmu1[0m[0;34m,[0m [0msigma[0m[0;34m=[0m[0msigma1[0m[0;34m)[0m[0;34m[0m[0;34m[0m[0m
[0m[1;32m      9[0m [0;34m[0m[0m
[1;32m     10[0m [0mnll1[0m [0;34m=[0m [0mapi_unbinned_nll[0m[0;34m([0m[0mgauss1[0m[0;34m,[0m [0mds_gauss_at_five[0m[0;34m,[0m [0;34m([0m[0;36m0[0m[0;34m,[0m [0;36m20[0m[0;34m)[0m[0;34m)[0m[0;34m[0m[0;34m[0m[0m

[0;31mTypeError[0m: __init__() missing 1 required positional argument: 'obs'
TypeError: __init__() missing 1 required positional argument: 'obs'

